Workbook
Name AsAt_Date: Assumptions!$D$13
Name Cat_ChargesVAT: Categories!$F$8:$F$18
Name Cat_Class: Categories!$D$8:$D$18
Name Cat_Codes: Categories!$B$8:$B$18
Name Cat_Direction: Categories!$E$8:$E$18
Name Cat_InputDeductible: Categories!$G$8:$G$18
Name Cat_Name: Categories!$C$8:$C$18
Name Cat_Rate: Categories!$M$8:$M$18
Name Cat_Recoverable: Categories!$N$8:$N$18
Name Combined_VAT_Rate: Assumptions!$D$25
Name COVID_Rate: Assumptions!$D$23
Name COVID_Rate_Prior: Assumptions!$D$24
Name Dir_In: Cash_Flow!$F$7
Name Dir_Out: Cash_Flow!$F$8
Name Dup_Exclusions: Error_Flags!$F$7:$H$7
Name GETFund_Rate: Assumptions!$D$22
Name Ledger_Year: Assumptions!$D$12
Name NHIL_Rate: Assumptions!$D$21
Name NoInv_Exempt: Error_Flags!$F$6
Name Opening_Cash: Cash_Flow!$F$6
Name Prefix_Inflow: Error_Flags!$F$9
Name Prefix_Outflow: Error_Flags!$F$10
Name Remit_Kw1: Cash_Flow!$F$10
Name Remit_Kw2: Cash_Flow!$G$10
Name Sim_End: Assumptions!$D$11
Name Sim_Start: Assumptions!$D$10
Name Suspect_Categories: Error_Flags!$F$11
Name Suspect_Keywords: Error_Flags!$F$12:$M$12
Name Tax_Authority: Cash_Flow!$F$9
Name Tax_Tolerance: Error_Flags!$F$8
Name VAT_Flat_Rate: Assumptions!$D$26
Name VAT_Rate: Assumptions!$D$20
Name VAT_Threshold_Goods: Assumptions!$D$27
Name VAT_Threshold_Services: Assumptions!$D$28
Name VAT_WHT_Rate: Assumptions!$D$29
Name VR_Output_Tax_Total: VAT_Recon!$C$17+VAT_Recon!$D$17+VAT_Recon!$E$17
Name VR_Withheld_At_Source: VAT_Recon!$G$30
Name WHT_Goods: Assumptions!$D$30
Name WHT_Services: Assumptions!$D$31
Name WHT_Threshold: Assumptions!$D$33
Name WHT_Works: Assumptions!$D$32

Sheet Assumptions
B1: NKABOM HAULAGE LTD — CORE TAX ENGINE
B2: Sheet 1 of 6 • Assumptions & Controlled Tax Parameters • Petroleum Products Haulage, Ghana
B3: SIMULATION ONLY — All entity, counterparty, invoice and transaction data in this workbook is fictitious. This workbook is a control and reporting tool, not tax advice. Confirm all rates with the Ghana Revenue Authority before filing.
B5: A. ENTITY & SIMULATION CONTROL PANEL
B6: Parameter | D6: Entry | H6: Notes
B7: Entity name | D7: Nkabom Haulage Ltd | H7: Simulated taxpayer. Not a real registered company.
B8: Business activity | D8: Petroleum products haulage | H8: Bulk fuel cartage for OMCs and BDCs; ancillary logistics services.
B9: Reporting currency | D9: GHS | H9: Ghana Cedi. All amounts in this workbook are stated in GHS.
B10: Simulation period — start | D10: 46023 | H10: Period chosen so that the rates in force under the VAT Act, 2025 (Act 1151) apply throughout.
B11: Simulation period — end | D11: 46387 | H11: Twelve monthly VAT periods, supporting monthly reconciliation and cash-flow reporting.
B12: Ledger year | D12: 2026 | H12: Calendar year the Ledger transactions fall in. Driven centrally — the Ledger reads this as Ledger_Year.
B13: Assumptions "As at" date | D13: 46286 | H13: Date the rates and thresholds below were last verified against primary sources.
B14: VAT registration status | D14: Registered | H14: Assumed registered and standard-rated; turnover exceeds the registration threshold in B.7.
B15: VAT withholding agent? | D15: No | H15: The company is not an appointed agent, but suffers VAT withholding on some customer receipts.
B16: Prepared by / Reviewed by | D16: Finance — Tax | H16: Update on each review cycle. Rates should be re-verified at least quarterly.
B18: B. CONTROLLED TAX RATES & THRESHOLDS — these are the ONLY places a rate should ever be changed
B19: Parameter Code | C19: Parameter | D19: Value | E19: Unit | F19: Effective From | G19: Effective To | H19: Description / How it is used in this workbook | I19: Source Document (primary) | J19: Section / Provision | K19: Source Type | L19: Source Reference
B20: VAT_Rate | C20: Value Added Tax — standard rate | D20: 0.15 | E20: % of taxable value | F20: 46023 | G20: Open | H20: Core VAT rate. Applied to the net (tax-exclusive) amount of standard-rated supplies made and received. | I20: Value Added Tax Act, 2025 (Act 1151), as explained in GRA guidance on the 2026 VAT reforms | J20: s.3 — imposition of VAT at the standard rate; GRA VAT tax-type guidance | K20: Statute + GRA | L20: https://gra.gov.gh/domestic-tax/tax-types/vat/
B21: NHIL_Rate | C21: National Health Insurance Levy (NHIL) | D21: 0.025 | E21: % of taxable value | F21: 46023 | G21: Open | H21: Charged on the same base as VAT. Recoverable as input tax from 1 Jan 2026 following re-coupling. | I21: National Health Insurance Act, 2012 (Act 852), as amended by the National Health Insurance (Amendment) Act, 2025 — source for input tax deductibility; base re-coupled to VAT by the Value Added Tax Act, 2025 (Act 1151) | J21: National Health Insurance (Amendment) Act, 2025, number to confirm — re-coupling of the levy to the VAT base and input tax deductibility; GRA 2026 VAT reform guidance — Confirm section in Act text | K21: Statute + GRA | L21: https://gra.gov.gh/domestic-tax/tax-types/vat/
B22: GETFund_Rate | C22: Ghana Education Trust Fund Levy (GETFund) | D22: 0.025 | E22: % of taxable value | F22: 46023 | G22: Open | H22: Charged on the same base as VAT. Recoverable as input tax from 1 Jan 2026 following re-coupling. | I22: Ghana Education Trust Fund (Amendment) Act, 2018 (Act 972), as further amended by the Ghana Education Trust Fund (Amendment) Act, 2025 — source for input tax deductibility; base re-coupled to VAT by the Value Added Tax Act, 2025 (Act 1151) | J22: Ghana Education Trust Fund (Amendment) Act, year and number to confirm — re-coupling of the levy to the VAT base and input tax deductibility; GRA 2026 VAT reform guidance — Confirm section in Act text | K22: Statute + GRA | L22: https://gra.gov.gh/domestic-tax/tax-types/vat/
B23: COVID_Rate | C23: COVID-19 Health Recovery Levy — current | D23: 0 | E23: % of taxable value | F23: 46023 | G23: Open | H23: ABOLISHED. Held at 0% so the levy stays visible in the engine and can be reinstated centrally if ever re-enacted. | I23: COVID-19 Health Recovery Levy Repeal Act, 2025 — abolishes the levy created by the COVID-19 Health Recovery Levy Act, 2021 (Act 1068) | J23: Repeal of the COVID-19 Health Recovery Levy Act, 2021 (Act 1068); GRA VAT tax-type guidance on the 2026 reforms | K23: Statute + GRA | L23: https://gra.gov.gh/domestic-tax/tax-types/vat/
B24: COVID_Rate_Prior | C24: COVID-19 Health Recovery Levy — superseded | D24: 0.01 | E24: % of taxable value | F24: 44317 | G24: 46022 | H24: HISTORIC ONLY — not used by any calculation. Retained to document the basis for periods before 1 Jan 2026. | I24: COVID-19 Health Recovery Levy Act, 2021 (Act 1068) | J24: Act 1068 (imposition of the 1% levy), in force to 31 December 2025 | K24: Statute + GRA | L24: https://gra.gov.gh/domestic-tax/tax-types/vat/
B25: Combined_VAT_Rate | C25: Combined effective VAT & levy rate | D25: =D20+D21+D22+D23 -> 0.2 | E25: % of taxable value | F25: =F20 -> 46023 | G25: Open | H25: DERIVED — do not overtype. VAT, NHIL and GETFund now sit on the same base, so the three simply add to 20%. This is the single rate the Ledger applies to standard-rated lines. | I25: Derived from VAT_Rate + NHIL_Rate + GETFund_Rate + COVID_Rate above | J25: Confirmed by GRA: the levies are charged on the same base as VAT (no cascading) | K25: Derived | L25: https://gra.gov.gh/domestic-tax/tax-types/vat/
B26: VAT_Flat_Rate | C26: VAT Flat Rate Scheme (VFRS) | D26: Abolished | E26: n/a — scheme withdrawn | F26: 46023 | G26: Open | H26: 3% and 5% flat rate regimes ended by Act 1151. All eligible suppliers use the 15% standard rate. | I26: Value Added Tax Act, 2025 (Act 1151) | J26: Abolition of the VAT Flat Rate Scheme; 3% on goods and 5% on immovable property withdrawn | K26: Statute + GRA | L26: https://gra.gov.gh/news/portfolio/notice-to-all-vat-registered-taxpayers/
B27: VAT_Threshold_Goods | C27: VAT registration threshold — goods | D27: 750000 | E27: GHS per annum | F27: 46023 | G27: Open | H27: Turnover level above which registration is compulsory for a goods business. Raised from GHS 200,000 by Act 1151. | I27: Value Added Tax Act, 2025 (Act 1151) | J27: Registration threshold — supply of goods | K27: GRA | L27: https://gra.gov.gh/news/portfolio/notice-to-all-vat-registered-taxpayers/
B28: VAT_Threshold_Services | C28: VAT registration threshold — services | D28: None | E28: Register within 30 days of starting taxable services | F28: 46023 | G28: Open | H28: No turnover test applies to this company. It registers regardless of turnover, on commencing taxable services, and accounts for VAT on all standard-rated supplies from day one. | I28: Value Added Tax Act, 2025 (Act 1151); GRA VAT tax-type guidance | J28: Registration obligation — supply of services; registration on commencement rather than by turnover | K28: Statute + GRA | L28: https://gra.gov.gh/news/portfolio/notice-to-all-vat-registered-taxpayers/
B29: VAT_WHT_Rate | C29: VAT withholding rate (appointed agents) | D29: 0.07 | E29: % of taxable value | F29: 46023 | G29: Open | H29: Withheld by appointed customers from amounts due to the company. A payment credit, not an extra tax — it does not change output VAT. Applies only when an appointed VAT withholding agent pays a VAT-registered supplier. Base is the tax-exclusive value. | I29: Ghana Revenue Authority — VAT Withholding guidance; Value Added Tax Act, 2025 (Act 1151) | J29: Act 1151 s.56, withholding of 7% of taxable output value. s.55, appointment of agents, confirm in Act text. | K29: GRA | L29: https://gra.gov.gh/domestic-tax/tax-types/vat-withholding/
B30: WHT_Goods | C30: Withholding tax — supply of goods (resident) | D30: 0.03 | E30: % of payment | F30: Not changed by Act 1151 | G30: Open | H30: Income-tax withholding on payments to resident suppliers of goods. Separate from VAT — kept here so the Ledger can reference it centrally. | I30: Income Tax Act, 2015 (Act 896), as amended | J30: First Schedule, paragraph 8 — withholding on supply of goods | K30: Statute | L30: https://gra.gov.gh/domestic-tax/tax-types/withholding-tax/
B31: WHT_Services | C31: Withholding tax — supply of services (resident) | D31: 0.075 | E31: % of payment | F31: Not changed by Act 1151 | G31: Open | H31: The rate most relevant to this company: haulage is a service, so customers who are withholding agents deduct 7.5% from fees. | I31: Income Tax Act, 2015 (Act 896), as amended | J31: First Schedule, paragraph 8 — withholding on service fees | K31: Statute | L31: https://gra.gov.gh/domestic-tax/tax-types/withholding-tax/
B32: WHT_Works | C32: Withholding tax — works (resident) | D32: 0.05 | E32: % of payment | F32: Not changed by Act 1151 | G32: Open | H32: Applies to works contracts, e.g. depot civil works. Included for completeness of the withholding category. | I32: Income Tax Act, 2015 (Act 896), as amended | J32: First Schedule, paragraph 8 — withholding on works | K32: Statute | L32: https://gra.gov.gh/domestic-tax/tax-types/withholding-tax/
B33: WHT_Threshold | C33: Withholding tax threshold (goods/works/services) | D33: 2000 | E33: GHS per annum cumulative per payee | F33: Not changed by Act 1151 | G33: Open | H33: Cumulative annual payments to one person below this level are not subject to withholding. Not a VAT threshold — do not confuse with VAT_Threshold_Goods / VAT_Threshold_Services. | I33: Income Tax Act, 2015 (Act 896), as amended; Ghana Revenue Authority — Withholding Tax page | J33: Sections 114–120 and First Schedule, paragraph 8 — GHS 2,000 contract rule | K33: Statute | L33: https://gra.gov.gh/domestic-tax/tax-types/withholding-tax/
B35: C. CONTROL CHECKS — all must read OK before the workbook is relied on
B36: Control check | D36: Expected | E36: Actual | F36: Status
B37: 1. Combined VAT & levy rate agrees to the 20% effective rate published by GRA | D37: 0.2 | E37: =D25 -> 0.2 | F37: =IF(ABS(E37-D37)<0.000001,"OK","REVIEW") -> OK
B38: 2. COVID-19 Health Recovery Levy is nil for the simulation period | D38: 0 | E38: =D23 -> 0 | F38: =IF(E38=D38,"OK","REVIEW") -> OK
B39: 3. Simulation period falls entirely inside the Act 1151 effective window | D39: Yes | E39: =IF(AND(D10>=F20,D11>=F20),"Yes","No") -> Yes | F39: =IF(E39=D39,"OK","REVIEW") -> OK
B40: 4. Every rate and threshold carries a primary source document | D40: 0 | E40: =COUNTBLANK(I20:I33) -> 0 | F40: =IF(E40=D40,"OK","REVIEW") -> OK
B41: 5. Every rate and threshold carries a section / provision reference | D41: 0 | E41: =COUNTBLANK(J20:J33) -> 0 | F41: =IF(E41=D41,"OK","REVIEW") -> OK
B42: 6. No rate, threshold or status cell has been left blank | D42: 0 | E42: =COUNTBLANK(D20:D33) -> 0 | F42: =IF(E42=D42,"OK","REVIEW") -> OK
B43: 7. Assumptions have been verified within the last 90 days | D43: Current | E43: =IF(TODAY()-D13<=90,"Current","Re-verify") -> Current | F43: =IF(E43=D43,"OK","REVIEW") -> OK
...

Sheet Categories
B1: NKABOM HAULAGE LTD — CORE TAX ENGINE
B2: Sheet 2 of 6 • Tax Category Reference • Controlled list — the Ledger validates against this sheet
B3: SIMULATION ONLY — This sheet sets the tax treatment applied to every Ledger line. Change a code here and every transaction using it re-calculates. Not tax advice.
B5: A. TAX CATEGORY REFERENCE TABLE
B7: Code | C7: Category Name | D7: VAT Class | E7: Direction | F7: Charges VAT | G7: Input Deductible | H7: Plain-language definition | I7: VAT / input-tax treatment | J7: Source document | K7: Section / provision | L7: Rate Named Range | M7: Rate | N7: Recoverable
B8: OUT_STD | C8: Standard-rated sale (output) | D8: Standard-rated | E8: Inflow | F8: Yes | G8: n/a - output | H8: Freight and haulage services the company invoices to customers in Ghana. The normal case for this business. | I8: Charge VAT 15% plus NHIL 2.5% and GETFund 2.5% on the tax-exclusive fee, a combined 20%. Declared as output tax on the monthly VAT return. | J8: Value Added Tax Act, 2025 (Act 1151); GRA VAT tax-type guidance | K8: s.3 - imposition of VAT at the standard rate | L8: Combined_VAT_Rate | M8: {=_xlfn.SWITCH(tbl_Categories[[#This Row],[Code]],"OUT_STD",Combined_VAT_Rate,"IN_STD",Combined_VAT_Rate,"IN_NONDED",Combined_VAT_Rate,"WHT_SVC",WHT_Services,"VAT_WHT",VAT_WHT_Rate,"WHT_GOODS",WHT_Goods,"WHT_WORKS",WHT_Works,0)} -> 0.2 | N8: Yes
B9: WHT_SVC | C9: Standard-rated sale, income tax withheld | D9: Standard-rated | E9: Inflow | F9: Yes | G9: n/a - output | H9: A standard-rated haulage sale where the customer is an income-tax withholding agent and deducts 7.5% from the service fee before paying. | I9: VAT treatment is unchanged - still 20% output tax on the full fee. The 7.5% deduction is income tax, not VAT, and is recovered as a tax credit. Never net it off output VAT. | J9: Value Added Tax Act, 2025 (Act 1151); Income Tax Act, 2015 (Act 896) | K9: First Schedule, paragraph 8 - withholding on service fees | L9: WHT_Services | M9: {=_xlfn.SWITCH(tbl_Categories[[#This Row],[Code]],"OUT_STD",Combined_VAT_Rate,"IN_STD",Combined_VAT_Rate,"IN_NONDED",Combined_VAT_Rate,"WHT_SVC",WHT_Services,"VAT_WHT",VAT_WHT_Rate,"WHT_GOODS",WHT_Goods,"WHT_WORKS",WHT_Works,0)} -> 0.075 | N9: No
B10: VAT_WHT | C10: Standard-rated sale, VAT withheld at source | D10: Standard-rated | E10: Inflow | F10: Yes | G10: n/a - output | H10: A standard-rated haulage sale to a customer GRA has appointed as a VAT withholding agent. The customer retains 7% of the taxable value and pays it to GRA directly. | I10: Output tax is still declared in full at 20%. The 7% withheld is a payment on account, claimed as a credit against the VAT liability on production of the withholding certificate. | J10: Value Added Tax Act, 2025 (Act 1151); GRA VAT Withholding guidance | K10: Act 1151 s.56, withholding of 7%; s.55, appointment of agents, confirm in Act text | L10: VAT_WHT_Rate | M10: {=_xlfn.SWITCH(tbl_Categories[[#This Row],[Code]],"OUT_STD",Combined_VAT_Rate,"IN_STD",Combined_VAT_Rate,"IN_NONDED",Combined_VAT_Rate,"WHT_SVC",WHT_Services,"VAT_WHT",VAT_WHT_Rate,"WHT_GOODS",WHT_Goods,"WHT_WORKS",WHT_Works,0)} -> 0.07 | N10: No
B11: IN_STD | C11: Standard-rated purchase (recoverable input) | D11: Standard-rated | E11: Outflow | F11: Yes | G11: Yes | H11: Purchases from VAT-registered suppliers used in making taxable supplies - spares, tyres, repairs, telecoms, professional fees. | I11: Input tax at 20% is recoverable in full and offset against output VAT. From 1 January 2026 the NHIL and GETFund elements are also recoverable, because Act 1151 re-coupled them to the VAT base. | J11: Value Added Tax Act, 2025 (Act 1151); GRA VAT tax-type guidance | K11: Deduction of input tax; re-coupling of NHIL and GETFund | L11: Combined_VAT_Rate | M11: {=_xlfn.SWITCH(tbl_Categories[[#This Row],[Code]],"OUT_STD",Combined_VAT_Rate,"IN_STD",Combined_VAT_Rate,"IN_NONDED",Combined_VAT_Rate,"WHT_SVC",WHT_Services,"VAT_WHT",VAT_WHT_Rate,"WHT_GOODS",WHT_Goods,"WHT_WORKS",WHT_Works,0)} -> 0.2 | N11: Yes
B12: IN_EXEMPT | C12: Exempt purchase | D12: Exempt | E12: Outflow | F12: No | G12: No | H12: Supplies that carry no VAT at all - in this business mainly petroleum products bought for own use, insurance premiums and bank charges. | I12: No VAT is charged by the supplier, so there is no input tax to claim. The full cost is expensed. Claiming input tax on these is a common and material error. | J12: Value Added Tax Act, 2025 (Act 1151) - exempt supplies | K12: Exempt supplies schedule - confirm item in Act text | L12: None - exempt | M12: {=_xlfn.SWITCH(tbl_Categories[[#This Row],[Code]],"OUT_STD",Combined_VAT_Rate,"IN_STD",Combined_VAT_Rate,"IN_NONDED",Combined_VAT_Rate,"WHT_SVC",WHT_Services,"VAT_WHT",VAT_WHT_Rate,"WHT_GOODS",WHT_Goods,"WHT_WORKS",WHT_Works,0)} -> 0 | N12: No
B13: NO_VAT | C13: Outside the scope of VAT | D13: Outside scope | E13: Outflow | F13: No | G13: No | H13: Payments that are not a supply of goods or services - salaries and wages, loan principal and interest, tax remittances, dividends and internal transfers. | I13: Not a taxable transaction. No VAT, no input tax and no entry on the VAT return. Included in the Ledger only so the cash-flow statement is complete. | J13: Value Added Tax Act, 2025 (Act 1151) - scope of the tax | K13: Scope - taxable supply made in Ghana by a taxable person | L13: None - outside scope | M13: {=_xlfn.SWITCH(tbl_Categories[[#This Row],[Code]],"OUT_STD",Combined_VAT_Rate,"IN_STD",Combined_VAT_Rate,"IN_NONDED",Combined_VAT_Rate,"WHT_SVC",WHT_Services,"VAT_WHT",VAT_WHT_Rate,"WHT_GOODS",WHT_Goods,"WHT_WORKS",WHT_Works,0)} -> 0 | N13: No
B14: IN_NONDED | C14: Non-deductible input | D14: Non-deductible | E14: Outflow | F14: Yes | G14: No | H14: Purchases where the supplier correctly charges VAT but the law blocks recovery - entertainment, staff hospitality and passenger vehicles. | I14: VAT at 20% is charged and paid, but none of it may be claimed as input tax. The VAT becomes part of the cost. This is the trap the Error_Flags sheet is designed to catch. | J14: Value Added Tax Act, 2025 (Act 1151) - restriction on input tax | K14: Blocked input tax - entertainment and passenger vehicles; confirm in Act text | L14: Combined_VAT_Rate | M14: {=_xlfn.SWITCH(tbl_Categories[[#This Row],[Code]],"OUT_STD",Combined_VAT_Rate,"IN_STD",Combined_VAT_Rate,"IN_NONDED",Combined_VAT_Rate,"WHT_SVC",WHT_Services,"VAT_WHT",VAT_WHT_Rate,"WHT_GOODS",WHT_Goods,"WHT_WORKS",WHT_Works,0)} -> 0.2 | N14: No
B15: ZERO_RATED | C15: Zero-rated supply | D15: Zero-rated | E15: Inflow | F15: No | G15: Yes | H15: Taxable supplies charged at 0% - chiefly exports qualifying under the Act. Held here for completeness; the simulated Ledger contains none. Charges VAT is set to No because the rate is 0%. Unlike an exempt supply, input tax on related costs stays recoverable - see Input Deductible. | I15: VAT is charged at 0%, so no output tax arises, but the supply stays taxable. Input tax on related costs remains fully recoverable - the key difference from an exempt supply. | J15: Value Added Tax Act, 2025 (Act 1151) - zero-rated supplies | K15: Zero-rating schedule - exports; confirm item in Act text | L15: None - zero-rated | M15: {=_xlfn.SWITCH(tbl_Categories[[#This Row],[Code]],"OUT_STD",Combined_VAT_Rate,"IN_STD",Combined_VAT_Rate,"IN_NONDED",Combined_VAT_Rate,"WHT_SVC",WHT_Services,"VAT_WHT",VAT_WHT_Rate,"WHT_GOODS",WHT_Goods,"WHT_WORKS",WHT_Works,0)} -> 0 | N15: No
B16: WHT_GOODS | C16: Purchase of goods with income tax withheld | D16: Standard-rated (input) | E16: Outflow | F16: Yes | G16: Yes | H16: A standard-rated purchase of goods from a resident supplier where the company must deduct income tax at source before paying. The VAT position and the withholding position are separate: VAT is charged on the supply in the normal way, while income tax is withheld from the payment. | I16: Input VAT, NHIL and GETFund are recoverable in the normal way. The amount withheld is an income tax credit for the supplier, not a reduction of VAT. Withhold only once cumulative payments to the supplier pass the GHS 2,000 annual threshold. | J16: Income Tax Act, 2015 (Act 896), as amended | K16: First Schedule, paragraph 8 — withholding on supply of goods | L16: WHT_Goods | M16: {=_xlfn.SWITCH(tbl_Categories[[#This Row],[Code]],"OUT_STD",Combined_VAT_Rate,"IN_STD",Combined_VAT_Rate,"IN_NONDED",Combined_VAT_Rate,"WHT_SVC",WHT_Services,"VAT_WHT",VAT_WHT_Rate,"WHT_GOODS",WHT_Goods,"WHT_WORKS",WHT_Works,0)} -> 0.03 | N16: No
B17: WHT_WORKS | C17: Works contract with income tax withheld | D17: Standard-rated (input) | E17: Outflow | F17: Yes | G17: Yes | H17: A standard-rated works contract, such as depot civil works or tank construction, from which the company must deduct income tax at source before paying the contractor. | I17: Input VAT, NHIL and GETFund are recoverable in the normal way. The amount withheld is an income tax credit for the contractor and does not affect the VAT return. Subject to the same GHS 2,000 cumulative threshold. | J17: Income Tax Act, 2015 (Act 896), as amended | K17: First Schedule, paragraph 8 — withholding on works | L17: WHT_Works | M17: {=_xlfn.SWITCH(tbl_Categories[[#This Row],[Code]],"OUT_STD",Combined_VAT_Rate,"IN_STD",Combined_VAT_Rate,"IN_NONDED",Combined_VAT_Rate,"WHT_SVC",WHT_Services,"VAT_WHT",VAT_WHT_Rate,"WHT_GOODS",WHT_Goods,"WHT_WORKS",WHT_Works,0)} -> 0.05 | N17: No
B18: OUT_EXEMPT | C18: Exempt supply made by the company | D18: Exempt (output) | E18: Inflow | F18: No | G18: No | H18: A sale by the company that is exempt from VAT, so no VAT, NHIL or GETFund is charged to the customer and none appears on the invoice. | I18: No output tax arises. Unlike a zero-rated supply, input tax attributable to making this supply is NOT recoverable and must be excluded from the input tax claim, which may require an apportionment where the company makes both exempt and taxable supplies. | J18: Value Added Tax Act, 2025 (Act 1151) | K18: Exempt supplies — First Schedule (exempt supplies list) | L18: None - exempt | M18: {=_xlfn.SWITCH(tbl_Categories[[#This Row],[Code]],"OUT_STD",Combined_VAT_Rate,"IN_STD",Combined_VAT_Rate,"IN_NONDED",Combined_VAT_Rate,"WHT_SVC",WHT_Services,"VAT_WHT",VAT_WHT_Rate,"WHT_GOODS",WHT_Goods,"WHT_WORKS",WHT_Works,0)} -> 0 | N18: No

Sheet Ledger
B1: NKABOM HAULAGE LTD — CORE TAX ENGINE
B2: Sheet 3 of 6 • Transaction Ledger • 1 January to 31 August 2026 • 300 simulated transactions
B3: SIMULATION ONLY — All counterparties, invoice numbers and amounts are fictitious. Blue cells are captured data. Grey cells are calculated — do not overtype. Tax Category is validated against the Categories sheet.
B5: A. TRANSACTION LEDGER
B6: All amounts in GHS. Amount is tax-exclusive. Tax Charged on Invoice is the figure as recorded on the source document — it is deliberately NOT a formula, so Error_Flags can compare it against the Expected columns.
B7: Row ID | C7: Date | D7: Description | E7: Counterparty | F7: Direction | G7: Tax Category | H7: Amount | I7: Invoice Number | J7: Tax Charged on Invoice | K7: Expected VAT | L7: Expected NHIL | M7: Expected GETFund | N7: Expected Total Tax | O7: Gross Amount
B8: 1 | C8: 46023 | D8: Bulk haulage of ATK, Kumasi-Sunyani, 9 trips | E8: Golden Harmattan Energy Ltd | F8: Inflow | G8: OUT_STD | H8: 19979 | I8: NHL-2026-0001 | J8: 3995.8 | K8: =IF(INDEX(Cat_ChargesVAT,MATCH(tbl_Ledger[[#This Row],[Tax Category]],Cat_Codes,0))="No",0,tbl_Ledger[[#This Row],[Amount]]*VAT_Rate) -> 2996.85 | L8: =IF(INDEX(Cat_ChargesVAT,MATCH(tbl_Ledger[[#This Row],[Tax Category]],Cat_Codes,0))="No",0,tbl_Ledger[[#This Row],[Amount]]*NHIL_Rate) -> 499.475 | M8: =IF(INDEX(Cat_ChargesVAT,MATCH(tbl_Ledger[[#This Row],[Tax Category]],Cat_Codes,0))="No",0,tbl_Ledger[[#This Row],[Amount]]*GETFund_Rate) -> 499.475 | N8: =tbl_Ledger[[#This Row],[Expected VAT]]+tbl_Ledger[[#This Row],[Expected NHIL]]+tbl_Ledger[[#This Row],[Expected GETFund]] -> 3995.8 | O8: =tbl_Ledger[[#This Row],[Amount]]+tbl_Ledger[[#This Row],[Tax Charged on Invoice]] -> 23974.8
B9: 2 | C9: 46025 | D9: Bulk haulage of ATK, Tema-Takoradi, 3 trips | E9: Tema Bulk Energy Ltd | F9: Inflow | G9: OUT_STD | H9: 63242 | I9: NHL-2026-0002 | J9: 12648.4 | K9: =IF(INDEX(Cat_ChargesVAT,MATCH(tbl_Ledger[[#This Row],[Tax Category]],Cat_Codes,0))="No",0,tbl_Ledger[[#This Row],[Amount]]*VAT_Rate) -> 9486.3 | L9: =IF(INDEX(Cat_ChargesVAT,MATCH(tbl_Ledger[[#This Row],[Tax Category]],Cat_Codes,0))="No",0,tbl_Ledger[[#This Row],[Amount]]*NHIL_Rate) -> 1581.05 | M9: =IF(INDEX(Cat_ChargesVAT,MATCH(tbl_Ledger[[#This Row],[Tax Category]],Cat_Codes,0))="No",0,tbl_Ledger[[#This Row],[Amount]]*GETFund_Rate) -> 1581.05 | N9: =tbl_Ledger[[#This Row],[Expected VAT]]+tbl_Ledger[[#This Row],[Expected NHIL]]+tbl_Ledger[[#This Row],[Expected GETFund]] -> 12648.4 | O9: =tbl_Ledger[[#This Row],[Amount]]+tbl_Ledger[[#This Row],[Tax Charged on Invoice]] -> 75890.4
B10: 3 | C10: 46026 | D10: Mobile and data services | E10: Sahara Fleet Services Ltd | F10: Outflow | G10: IN_STD | H10: 1670 | I10: SIN-2026-0001 | J10: 334 | K10: =IF(INDEX(Cat_ChargesVAT,MATCH(tbl_Ledger[[#This Row],[Tax Category]],Cat_Codes,0))="No",0,tbl_Ledger[[#This Row],[Amount]]*VAT_Rate) -> 250.5 | L10: =IF(INDEX(Cat_ChargesVAT,MATCH(tbl_Ledger[[#This Row],[Tax Category]],Cat_Codes,0))="No",0,tbl_Ledger[[#This Row],[Amount]]*NHIL_Rate) -> 41.75 | M10: =IF(INDEX(Cat_ChargesVAT,MATCH(tbl_Ledger[[#This Row],[Tax Category]],Cat_Codes,0))="No",0,tbl_Ledger[[#This Row],[Amount]]*GETFund_Rate) -> 41.75 | N10: =tbl_Ledger[[#This Row],[Expected VAT]]+tbl_Ledger[[#This Row],[Expected NHIL]]+tbl_Ledger[[#This Row],[Expected GETFund]] -> 334 | O10: =tbl_Ledger[[#This Row],[Amount]]+tbl_Ledger[[#This Row],[Tax Charged on Invoice]] -> 2004
B11: 4 | C11: 46027 | D11: Contract haulage of PMS, Tema-Ho; customer withheld income tax at 7.5% on the service fee | E11: Tema Bulk Energy Ltd | F11: Inflow | G11: WHT_SVC | H11: 68614 | I11: NHL-2026-0003 | J11: 13722.8 | K11: =IF(INDEX(Cat_ChargesVAT,MATCH(tbl_Ledger[[#This Row],[Tax Category]],Cat_Codes,0))="No",0,tbl_Ledger[[#This Row],[Amount]]*VAT_Rate) -> 10292.1 | L11: =IF(INDEX(Cat_ChargesVAT,MATCH(tbl_Ledger[[#This Row],[Tax Category]],Cat_Codes,0))="No",0,tbl_Ledger[[#This Row],[Amount]]*NHIL_Rate) -> 1715.35 | M11: =IF(INDEX(Cat_ChargesVAT,MATCH(tbl_Ledger[[#This Row],[Tax Category]],Cat_Codes,0))="No",0,tbl_Ledger[[#This Row],[Amount]]*GETFund_Rate) -> 1715.35 | N11: =tbl_Ledger[[#This Row],[Expected VAT]]+tbl_Ledger[[#This Row],[Expected NHIL]]+tbl_Ledger[[#This Row],[Expected GETFund]] -> 13722.8 | O11: =tbl_Ledger[[#This Row],[Amount]]+tbl_Ledger[[#This Row],[Tax Charged on Invoice]] -> 82336.8
B12: 5 | C12: 46028 | D12: Bulk haulage of AGO, Tema-Bolgatanga, 2 trips | E12: Sankofa Petroleum Depot Ltd | F12: Inflow | G12: OUT_STD | H12: 66547 | I12: NHL-2026-0004 | J12: 13309.4 | K12: =IF(INDEX(Cat_ChargesVAT,MATCH(tbl_Ledger[[#This Row],[Tax Category]],Cat_Codes,0))="No",0,tbl_Ledger[[#This Row],[Amount]]*VAT_Rate) -> 9982.05 | L12: =IF(INDEX(Cat_ChargesVAT,MATCH(tbl_Ledger[[#This Row],[Tax Category]],Cat_Codes,0))="No",0,tbl_Ledger[[#This Row],[Amount]]*NHIL_Rate) -> 1663.675 | M12: =IF(INDEX(Cat_ChargesVAT,MATCH(tbl_Ledger[[#This Row],[Tax Category]],Cat_Codes,0))="No",0,tbl_Ledger[[#This Row],[Amount]]*GETFund_Rate) -> 1663.675 | N12: =tbl_Ledger[[#This Row],[Expected VAT]]+tbl_Ledger[[#This Row],[Expected NHIL]]+tbl_Ledger[[#This Row],[Expected GETFund]] -> 13309.4 | O12: =tbl_Ledger[[#This Row],[Amount]]+tbl_Ledger[[#This Row],[Tax Charged on Invoice]] -> 79856.4
B13: 6 | C13: 46028 | D13: Contract haulage of AGO, Tema-Bolgatanga; customer withheld income tax at 7.5% on the service fee | E13: Tema Bulk Energy Ltd | F13: Inflow | G13: WHT_SVC | H13: 58678 | I13: NHL-2026-0005 | J13: 11735.6 | K13: =IF(INDEX(Cat_ChargesVAT,MATCH(tbl_Ledger[[#This Row],[Tax Category]],Cat_Codes,0))="No",0,tbl_Ledger[[#This Row],[Amount]]*VAT_Rate) -> 8801.7 | L13: =IF(INDEX(Cat_ChargesVAT,MATCH(tbl_Ledger[[#This Row],[Tax Category]],Cat_Codes,0))="No",0,tbl_Ledger[[#This Row],[Amount]]*NHIL_Rate) -> 1466.95 | M13: =IF(INDEX(Cat_ChargesVAT,MATCH(tbl_Ledger[[#This Row],[Tax Category]],Cat_Codes,0))="No",0,tbl_Ledger[[#This Row],[Amount]]*GETFund_Rate) -> 1466.95 | N13: =tbl_Ledger[[#This Row],[Expected VAT]]+tbl_Ledger[[#This Row],[Expected NHIL]]+tbl_Ledger[[#This Row],[Expected GETFund]] -> 11735.6 | O13: =tbl_Ledger[[#This Row],[Amount]]+tbl_Ledger[[#This Row],[Tax Charged on Invoice]] -> 70413.6
B14: 7 | C14: 46029 | D14: Bulk haulage of AGO, Takoradi-Wa, 7 trips | E14: Golden Harmattan Energy Ltd | F14: Inflow | G14: OUT_STD | H14: 90933 | I14: NHL-2026-0006 | J14: 18186.6 | K14: =IF(INDEX(Cat_ChargesVAT,MATCH(tbl_Ledger[[#This Row],[Tax Category]],Cat_Codes,0))="No",0,tbl_Ledger[[#This Row],[Amount]]*VAT_Rate) -> 13639.95 | L14: =IF(INDEX(Cat_ChargesVAT,MATCH(tbl_Ledger[[#This Row],[Tax Category]],Cat_Codes,0))="No",0,tbl_Ledger[[#This Row],[Amount]]*NHIL_Rate) -> 2273.325 | M14: =IF(INDEX(Cat_ChargesVAT,MATCH(tbl_Ledger[[#This Row],[Tax Category]],Cat_Codes,0))="No",0,tbl_Ledger[[#This Row],[Amount]]*GETFund_Rate) -> 2273.325 | N14: =tbl_Ledger[[#This Row],[Expected VAT]]+tbl_Ledger[[#This Row],[Expected NHIL]]+tbl_Ledger[[#This Row],[Expected GETFund]] -> 18186.6 | O14: =tbl_Ledger[[#This Row],[Amount]]+tbl_Ledger[[#This Row],[Tax Charged on Invoice]] -> 109119.6
B15: 8 | C15: 46032 | D15: Diesel (AGO) purchased for own fleet use, 10,136 litres | E15: Zenith Fuel Depot Ltd | F15: Outflow | G15: IN_EXEMPT | H15: 60137 | I15: SIN-2026-0002 | J15: 0 | K15: =IF(INDEX(Cat_ChargesVAT,MATCH(tbl_Ledger[[#This Row],[Tax Category]],Cat_Codes,0))="No",0,tbl_Ledger[[#This Row],[Amount]]*VAT_Rate) -> 0 | L15: =IF(INDEX(Cat_ChargesVAT,MATCH(tbl_Ledger[[#This Row],[Tax Category]],Cat_Codes,0))="No",0,tbl_Ledger[[#This Row],[Amount]]*NHIL_Rate) -> 0 | M15: =IF(INDEX(Cat_ChargesVAT,MATCH(tbl_Ledger[[#This Row],[Tax Category]],Cat_Codes,0))="No",0,tbl_Ledger[[#This Row],[Amount]]*GETFund_Rate) -> 0 | N15: =tbl_Ledger[[#This Row],[Expected VAT]]+tbl_Ledger[[#This Row],[Expected NHIL]]+tbl_Ledger[[#This Row],[Expected GETFund]] -> 0 | O15: =tbl_Ledger[[#This Row],[Amount]]+tbl_Ledger[[#This Row],[Tax Charged on Invoice]] -> 60137
B16: 9 | C16: 46032 | D16: Diesel (AGO) purchased for own fleet use, 8,242 litres | E16: Zenith Fuel Depot Ltd | F16: Outflow | G16: IN_EXEMPT | H16: 44086 | I16: SIN-2026-0003 | J16: 0 | K16: =IF(INDEX(Cat_ChargesVAT,MATCH(tbl_Ledger[[#This Row],[Tax Category]],Cat_Codes,0))="No",0,tbl_Ledger[[#This Row],[Amount]]*VAT_Rate) -> 0 | L16: =IF(INDEX(Cat_ChargesVAT,MATCH(tbl_Ledger[[#This Row],[Tax Category]],Cat_Codes,0))="No",0,tbl_Ledger[[#This Row],[Amount]]*NHIL_Rate) -> 0 | M16: =IF(INDEX(Cat_ChargesVAT,MATCH(tbl_Ledger[[#This Row],[Tax Category]],Cat_Codes,0))="No",0,tbl_Ledger[[#This Row],[Amount]]*GETFund_Rate) -> 0 | N16: =tbl_Ledger[[#This Row],[Expected VAT]]+tbl_Ledger[[#This Row],[Expected NHIL]]+tbl_Ledger[[#This Row],[Expected GETFund]] -> 0 | O16: =tbl_Ledger[[#This Row],[Amount]]+tbl_Ledger[[#This Row],[Tax Charged on Invoice]] -> 44086
B17: 10 | C17: 46034 | D17: Diesel (AGO) purchased for own fleet use, 16,629 litres | E17: Zenith Fuel Depot Ltd | F17: Outflow | G17: IN_EXEMPT | H17: 77769 | I17: SIN-2026-0004 | J17: 0 | K17: =IF(INDEX(Cat_ChargesVAT,MATCH(tbl_Ledger[[#This Row],[Tax Category]],Cat_Codes,0))="No",0,tbl_Ledger[[#This Row],[Amount]]*VAT_Rate) -> 0 | L17: =IF(INDEX(Cat_ChargesVAT,MATCH(tbl_Ledger[[#This Row],[Tax Category]],Cat_Codes,0))="No",0,tbl_Ledger[[#This Row],[Amount]]*NHIL_Rate) -> 0 | M17: =IF(INDEX(Cat_ChargesVAT,MATCH(tbl_Ledger[[#This Row],[Tax Category]],Cat_Codes,0))="No",0,tbl_Ledger[[#This Row],[Amount]]*GETFund_Rate) -> 0 | N17: =tbl_Ledger[[#This Row],[Expected VAT]]+tbl_Ledger[[#This Row],[Expected NHIL]]+tbl_Ledger[[#This Row],[Expected GETFund]] -> 0 | O17: =tbl_Ledger[[#This Row],[Amount]]+tbl_Ledger[[#This Row],[Tax Charged on Invoice]] -> 77769
B18: 11 | C18: 46036 | D18: PAYE and SSNIT contributions - January | E18: Ghana Revenue Authority | F18: Outflow | G18: NO_VAT | H18: 25595 | I18: GRA-2026-0001 | J18: 0 | K18: =IF(INDEX(Cat_ChargesVAT,MATCH(tbl_Ledger[[#This Row],[Tax Category]],Cat_Codes,0))="No",0,tbl_Ledger[[#This Row],[Amount]]*VAT_Rate) -> 0 | L18: =IF(INDEX(Cat_ChargesVAT,MATCH(tbl_Ledger[[#This Row],[Tax Category]],Cat_Codes,0))="No",0,tbl_Ledger[[#This Row],[Amount]]*NHIL_Rate) -> 0 | M18: =IF(INDEX(Cat_ChargesVAT,MATCH(tbl_Ledger[[#This Row],[Tax Category]],Cat_Codes,0))="No",0,tbl_Ledger[[#This Row],[Amount]]*GETFund_Rate) -> 0 | N18: =tbl_Ledger[[#This Row],[Expected VAT]]+tbl_Ledger[[#This Row],[Expected NHIL]]+tbl_Ledger[[#This Row],[Expected GETFund]] -> 0 | O18: =tbl_Ledger[[#This Row],[Amount]]+tbl_Ledger[[#This Row],[Tax Charged on Invoice]] -> 25595
B19: 12 | C19: 46037 | D19: Term loan repayment - principal and interest, instalment 1 | E19: Meridian Bank Ghana Ltd | F19: Outflow | G19: NO_VAT | H19: 41833 | I19: LN-2026-0001 | J19: 0 | K19: =IF(INDEX(Cat_ChargesVAT,MATCH(tbl_Ledger[[#This Row],[Tax Category]],Cat_Codes,0))="No",0,tbl_Ledger[[#This Row],[Amount]]*VAT_Rate) -> 0 | L19: =IF(INDEX(Cat_ChargesVAT,MATCH(tbl_Ledger[[#This Row],[Tax Category]],Cat_Codes,0))="No",0,tbl_Ledger[[#This Row],[Amount]]*NHIL_Rate) -> 0 | M19: =IF(INDEX(Cat_ChargesVAT,MATCH(tbl_Ledger[[#This Row],[Tax Category]],Cat_Codes,0))="No",0,tbl_Ledger[[#This Row],[Amount]]*GETFund_Rate) -> 0 | N19: =tbl_Ledger[[#This Row],[Expected VAT]]+tbl_Ledger[[#This Row],[Expected NHIL]]+tbl_Ledger[[#This Row],[Expected GETFund]] -> 0 | O19: =tbl_Ledger[[#This Row],[Amount]]+tbl_Ledger[[#This Row],[Tax Charged on Invoice]] -> 41833
... B99: 92 | C99: 46094 | D99: Term haulage contract, ATK, Tema-Bolgatanga; customer is an appointed VAT withholding agent and retained 7% | E99: Northern Star BDC Ltd | F99: Inflow | G99: VAT_WHT | H99: 79662 | I99: NHL-2026-0043 | J99: 15932.4 | K99: =IF(INDEX(Cat_ChargesVAT,MATCH(tbl_Ledger[[#This Row],[Tax Category]],Cat_Codes,0))="No",0,tbl_Ledger[[#This Row],[Amount]]*VAT_Rate) -> 11949.3 | L99: =IF(INDEX(Cat_ChargesVAT,MATCH(tbl_Ledger[[#This Row],[Tax Category]],Cat_Codes,0))="No",0,tbl_Ledger[[#This Row],[Amount]]*NHIL_Rate) -> 1991.55 | M99: =IF(INDEX(Cat_ChargesVAT,MATCH(tbl_Ledger[[#This Row],[Tax Category]],Cat_Codes,0))="No",0,tbl_Ledger[[#This Row],[Amount]]*GETFund_Rate) -> 1991.55 | N99: =tbl_Ledger[[#This Row],[Expected VAT]]+tbl_Ledger[[#This Row],[Expected NHIL]]+tbl_Ledger[[#This Row],[Expected GETFund]] -> 15932.4 | O99: =tbl_Ledger[[#This Row],[Amount]]+tbl_Ledger[[#This Row],[Tax Charged on Invoice]] -> 95594.4
B100: 93 | C100: 46095 | D100: Bulk haulage of AGO, Tema-Cape Coast, 6 trips | E100: Northern Star BDC Ltd | F100: Inflow | G100: OUT_STD | H100: 92487 | J100: 18497.4 | K100: =IF(INDEX(Cat_ChargesVAT,MATCH(tbl_Ledger[[#This Row],[Tax Category]],Cat_Codes,0))="No",0,tbl_Ledger[[#This Row],[Amount]]*VAT_Rate) -> 13873.05 | L100: =IF(INDEX(Cat_ChargesVAT,MATCH(tbl_Ledger[[#This Row],[Tax Category]],Cat_Codes,0))="No",0,tbl_Ledger[[#This Row],[Amount]]*NHIL_Rate) -> 2312.175 | M100: =IF(INDEX(Cat_ChargesVAT,MATCH(tbl_Ledger[[#This Row],[Tax Category]],Cat_Codes,0))="No",0,tbl_Ledger[[#This Row],[Amount]]*GETFund_Rate) -> 2312.175 | N100: =tbl_Ledger[[#This Row],[Expected VAT]]+tbl_Ledger[[#This Row],[Expected NHIL]]+tbl_Ledger[[#This Row],[Expected GETFund]] -> 18497.4 | O100: =tbl_Ledger[[#This Row],[Amount]]+tbl_Ledger[[#This Row],[Tax Charged on Invoice]] -> 110984.4
B101: 94 | C101: 46096 | D101: Passenger vehicle running costs - management car | E101: Sunset Lounge Ltd | F101: Outflow | G101: IN_NONDED | H101: 1960 | I101: SIN-2026-0031 | J101: 392 | K101: =IF(INDEX(Cat_ChargesVAT,MATCH(tbl_Ledger[[#This Row],[Tax Category]],Cat_Codes,0))="No",0,tbl_Ledger[[#This Row],[Amount]]*VAT_Rate) -> 294 | L101: =IF(INDEX(Cat_ChargesVAT,MATCH(tbl_Ledger[[#This Row],[Tax Category]],Cat_Codes,0))="No",0,tbl_Ledger[[#This Row],[Amount]]*NHIL_Rate) -> 49 | M101: =IF(INDEX(Cat_ChargesVAT,MATCH(tbl_Ledger[[#This Row],[Tax Category]],Cat_Codes,0))="No",0,tbl_Ledger[[#This Row],[Amount]]*GETFund_Rate) -> 49 | N101: =tbl_Ledger[[#This Row],[Expected VAT]]+tbl_Ledger[[#This Row],[Expected NHIL]]+tbl_Ledger[[#This Row],[Expected GETFund]] -> 392 | O101: =tbl_Ledger[[#This Row],[Amount]]+tbl_Ledger[[#This Row],[Tax Charged on Invoice]] -> 2352
B102: 95 | C102: 46096 | D102: Workshop consumables and lubricants | E102: Adom Telecom Ghana Ltd | F102: Outflow | G102: IN_STD | H102: 8703 | I102: SIN-2026-0032 | J102: 1740.6 | K102: =IF(INDEX(Cat_ChargesVAT,MATCH(tbl_Ledger[[#This Row],[Tax Category]],Cat_Codes,0))="No",0,tbl_Ledger[[#This Row],[Amount]]*VAT_Rate) -> 1305.45 | L102: =IF(INDEX(Cat_ChargesVAT,MATCH(tbl_Ledger[[#This Row],[Tax Category]],Cat_Codes,0))="No",0,tbl_Ledger[[#This Row],[Amount]]*NHIL_Rate) -> 217.575 | M102: =IF(INDEX(Cat_ChargesVAT,MATCH(tbl_Ledger[[#This Row],[Tax Category]],Cat_Codes,0))="No",0,tbl_Ledger[[#This Row],[Amount]]*GETFund_Rate) -> 217.575 | N102: =tbl_Ledger[[#This Row],[Expected VAT]]+tbl_Ledger[[#This Row],[Expected NHIL]]+tbl_Ledger[[#This Row],[Expected GETFund]] -> 1740.6 | O102: =tbl_Ledger[[#This Row],[Amount]]+tbl_Ledger[[#This Row],[Tax Charged on Invoice]] -> 10443.6
B103: 96 | C103: 46096 | D103: Term loan repayment - principal and interest, instalment 3 | E103: Meridian Bank Ghana Ltd | F103: Outflow | G103: NO_VAT | H103: 44143 | I103: LN-2026-0003 | J103: 0 | K103: =IF(INDEX(Cat_ChargesVAT,MATCH(tbl_Ledger[[#This Row],[Tax Category]],Cat_Codes,0))="No",0,tbl_Ledger[[#This Row],[Amount]]*VAT_Rate) -> 0 | L103: =IF(INDEX(Cat_ChargesVAT,MATCH(tbl_Ledger[[#This Row],[Tax Category]],Cat_Codes,0))="No",0,tbl_Ledger[[#This Row],[Amount]]*NHIL_Rate) -> 0 | M103: =IF(INDEX(Cat_ChargesVAT,MATCH(tbl_Ledger[[#This Row],[Tax Category]],Cat_Codes,0))="No",0,tbl_Ledger[[#This Row],[Amount]]*GETFund_Rate) -> 0 | N103: =tbl_Ledger[[#This Row],[Expected VAT]]+tbl_Ledger[[#This Row],[Expected NHIL]]+tbl_Ledger[[#This Row],[Expected GETFund]] -> 0 | O103: =tbl_Ledger[[#This Row],[Amount]]+tbl_Ledger[[#This Row],[Tax Charged on Invoice]] -> 44143
B104: 97 | C104: 46096 | D104: Bulk haulage of AGO, Takoradi-Wa, 7 trips | E104: Pra River Energy Ltd | F104: Inflow | G104: OUT_STD | H104: 59848 | I104: NHL-2026-0045 | J104: 11969.6 | K104: =IF(INDEX(Cat_ChargesVAT,MATCH(tbl_Ledger[[#This Row],[Tax Category]],Cat_Codes,0))="No",0,tbl_Ledger[[#This Row],[Amount]]*VAT_Rate) -> 8977.2 | L104: =IF(INDEX(Cat_ChargesVAT,MATCH(tbl_Ledger[[#This Row],[Tax Category]],Cat_Codes,0))="No",0,tbl_Ledger[[#This Row],[Amount]]*NHIL_Rate) -> 1496.2 | M104: =IF(INDEX(Cat_ChargesVAT,MATCH(tbl_Ledger[[#This Row],[Tax Category]],Cat_Codes,0))="No",0,tbl_Ledger[[#This Row],[Amount]]*GETFund_Rate) -> 1496.2 | N104: =tbl_Ledger[[#This Row],[Expected VAT]]+tbl_Ledger[[#This Row],[Expected NHIL]]+tbl_Ledger[[#This Row],[Expected GETFund]] -> 11969.6 | O104: =tbl_Ledger[[#This Row],[Amount]]+tbl_Ledger[[#This Row],[Tax Charged on Invoice]] -> 71817.6
B105: 98 | C105: 46098 | D105: Diesel (AGO) purchased for own fleet use, 17,746 litres | E105: Zenith Fuel Depot Ltd | F105: Outflow | G105: IN_EXEMPT | H105: 52490 | I105: SIN-2026-0033 | J105: 0 | K105: =IF(INDEX(Cat_ChargesVAT,MATCH(tbl_Ledger[[#This Row],[Tax Category]],Cat_Codes,0))="No",0,tbl_Ledger[[#This Row],[Amount]]*VAT_Rate) -> 0 | L105: =IF(INDEX(Cat_ChargesVAT,MATCH(tbl_Ledger[[#This Row],[Tax Category]],Cat_Codes,0))="No",0,tbl_Ledger[[#This Row],[Amount]]*NHIL_Rate) -> 0 | M105: =IF(INDEX(Cat_ChargesVAT,MATCH(tbl_Ledger[[#This Row],[Tax Category]],Cat_Codes,0))="No",0,tbl_Ledger[[#This Row],[Amount]]*GETFund_Rate) -> 0 | N105: =tbl_Ledger[[#This Row],[Expected VAT]]+tbl_Ledger[[#This Row],[Expected NHIL]]+tbl_Ledger[[#This Row],[Expected GETFund]] -> 0 | O105: =tbl_Ledger[[#This Row],[Amount]]+tbl_Ledger[[#This Row],[Tax Charged on Invoice]] -> 52490
B106: 99 | C106: 46098 | D106: Workshop consumables and lubricants | E106: Bono Workshop Services Ltd | F106: Outflow | G106: IN_STD | H106: 4906 | I106: SIN-2026-0081 | J106: 981.2 | K106: =IF(INDEX(Cat_ChargesVAT,MATCH(tbl_Ledger[[#This Row],[Tax Category]],Cat_Codes,0))="No",0,tbl_Ledger[[#This Row],[Amount]]*VAT_Rate) -> 735.9 | L106: =IF(INDEX(Cat_ChargesVAT,MATCH(tbl_Ledger[[#This Row],[Tax Category]],Cat_Codes,0))="No",0,tbl_Ledger[[#This Row],[Amount]]*NHIL_Rate) -> 122.65 | M106: =IF(INDEX(Cat_ChargesVAT,MATCH(tbl_Ledger[[#This Row],[Tax Category]],Cat_Codes,0))="No",0,tbl_Ledger[[#This Row],[Amount]]*GETFund_Rate) -> 122.65 | N106: =tbl_Ledger[[#This Row],[Expected VAT]]+tbl_Ledger[[#This Row],[Expected NHIL]]+tbl_Ledger[[#This Row],[Expected GETFund]] -> 981.2 | O106: =tbl_Ledger[[#This Row],[Amount]]+tbl_Ledger[[#This Row],[Tax Charged on Invoice]] -> 5887.2
B107: 100 | C107: 46099 | D107: Contract haulage of ATK, Takoradi-Wa; customer withheld income tax at 7.5% on the service fee | E107: Tema Bulk Energy Ltd | F107: Inflow | G107: WHT_SVC | H107: 49260 | I107: NHL-2026-0046 | J107: 9852 | K107: =IF(INDEX(Cat_ChargesVAT,MATCH(tbl_Ledger[[#This Row],[Tax Category]],Cat_Codes,0))="No",0,tbl_Ledger[[#This Row],[Amount]]*VAT_Rate) -> 7389 | L107: =IF(INDEX(Cat_ChargesVAT,MATCH(tbl_Ledger[[#This Row],[Tax Category]],Cat_Codes,0))="No",0,tbl_Ledger[[#This Row],[Amount]]*NHIL_Rate) -> 1231.5 | M107: =IF(INDEX(Cat_ChargesVAT,MATCH(tbl_Ledger[[#This Row],[Tax Category]],Cat_Codes,0))="No",0,tbl_Ledger[[#This Row],[Amount]]*GETFund_Rate) -> 1231.5 | N107: =tbl_Ledger[[#This Row],[Expected VAT]]+tbl_Ledger[[#This Row],[Expected NHIL]]+tbl_Ledger[[#This Row],[Expected GETFund]] -> 9852 | O107: =tbl_Ledger[[#This Row],[Amount]]+tbl_Ledger[[#This Row],[Tax Charged on Invoice]] -> 59112
B108: 101 | C108: 46100 | D108: Transfer and settlement charges | E108: Meridian Bank Ghana Ltd | F108: Outflow | G108: IN_EXEMPT | H108: 521 | I108: BNK-2026-0010 | J108: 104.2 | K108: =IF(INDEX(Cat_ChargesVAT,MATCH(tbl_Ledger[[#This Row],[Tax Category]],Cat_Codes,0))="No",0,tbl_Ledger[[#This Row],[Amount]]*VAT_Rate) -> 0 | L108: =IF(INDEX(Cat_ChargesVAT,MATCH(tbl_Ledger[[#This Row],[Tax Category]],Cat_Codes,0))="No",0,tbl_Ledger[[#This Row],[Amount]]*NHIL_Rate) -> 0 | M108: =IF(INDEX(Cat_ChargesVAT,MATCH(tbl_Ledger[[#This Row],[Tax Category]],Cat_Codes,0))="No",0,tbl_Ledger[[#This Row],[Amount]]*GETFund_Rate) -> 0 | N108: =tbl_Ledger[[#This Row],[Expected VAT]]+tbl_Ledger[[#This Row],[Expected NHIL]]+tbl_Ledger[[#This Row],[Expected GETFund]] -> 0 | O108: =tbl_Ledger[[#This Row],[Amount]]+tbl_Ledger[[#This Row],[Tax Charged on Invoice]] -> 625.2
B109: 102 | C109: 46100 | D109: Motor fleet insurance premium | E109: Unity Assurance Ltd | F109: Outflow | G109: IN_EXEMPT | H109: 31040 | I109: SIN-2026-0035 | J109: 0 | K109: =IF(INDEX(Cat_ChargesVAT,MATCH(tbl_Ledger[[#This Row],[Tax Category]],Cat_Codes,0))="No",0,tbl_Ledger[[#This Row],[Amount]]*VAT_Rate) -> 0 | L109: =IF(INDEX(Cat_ChargesVAT,MATCH(tbl_Ledger[[#This Row],[Tax Category]],Cat_Codes,0))="No",0,tbl_Ledger[[#This Row],[Amount]]*NHIL_Rate) -> 0 | M109: =IF(INDEX(Cat_ChargesVAT,MATCH(tbl_Ledger[[#This Row],[Tax Category]],Cat_Codes,0))="No",0,tbl_Ledger[[#This Row],[Amount]]*GETFund_Rate) -> 0 | N109: =tbl_Ledger[[#This Row],[Expected VAT]]+tbl_Ledger[[#This Row],[Expected NHIL]]+tbl_Ledger[[#This Row],[Expected GETFund]] -> 0 | O109: =tbl_Ledger[[#This Row],[Amount]]+tbl_Ledger[[#This Row],[Tax Charged on Invoice]] -> 31040
B110: 103 | C110: 46101 | D110: Motor fleet insurance premium | E110: Pillar Insurance Ghana Ltd | F110: Outflow | G110: IN_STD | H110: 21750 | I110: SIN-2026-0036 | J110: 4350 | K110: =IF(INDEX(Cat_ChargesVAT,MATCH(tbl_Ledger[[#This Row],[Tax Category]],Cat_Codes,0))="No",0,tbl_Ledger[[#This Row],[Amount]]*VAT_Rate) -> 3262.5 | L110: =IF(INDEX(Cat_ChargesVAT,MATCH(tbl_Ledger[[#This Row],[Tax Category]],Cat_Codes,0))="No",0,tbl_Ledger[[#This Row],[Amount]]*NHIL_Rate) -> 543.75 | M110: =IF(INDEX(Cat_ChargesVAT,MATCH(tbl_Ledger[[#This Row],[Tax Category]],Cat_Codes,0))="No",0,tbl_Ledger[[#This Row],[Amount]]*GETFund_Rate) -> 543.75 | N110: =tbl_Ledger[[#This Row],[Expected VAT]]+tbl_Ledger[[#This Row],[Expected NHIL]]+tbl_Ledger[[#This Row],[Expected GETFund]] -> 4350 | O110: =tbl_Ledger[[#This Row],[Amount]]+tbl_Ledger[[#This Row],[Tax Charged on Invoice]] -> 26100
B111: 104 | C111: 46104 | D111: Diesel (AGO) purchased for own fleet use, 21,989 litres | E111: Zenith Fuel Depot Ltd | F111: Outflow | G111: IN_EXEMPT | H111: 82343 | I111: SIN-2026-0037 | J111: 0 | K111: =IF(INDEX(Cat_ChargesVAT,MATCH(tbl_Ledger[[#This Row],[Tax Category]],Cat_Codes,0))="No",0,tbl_Ledger[[#This Row],[Amount]]*VAT_Rate) -> 0 | L111: =IF(INDEX(Cat_ChargesVAT,MATCH(tbl_Ledger[[#This Row],[Tax Category]],Cat_Codes,0))="No",0,tbl_Ledger[[#This Row],[Amount]]*NHIL_Rate) -> 0 | M111: =IF(INDEX(Cat_ChargesVAT,MATCH(tbl_Ledger[[#This Row],[Tax Category]],Cat_Codes,0))="No",0,tbl_Ledger[[#This Row],[Amount]]*GETFund_Rate) -> 0 | N111: =tbl_Ledger[[#This Row],[Expected VAT]]+tbl_Ledger[[#This Row],[Expected NHIL]]+tbl_Ledger[[#This Row],[Expected GETFund]] -> 0 | O111: =tbl_Ledger[[#This Row],[Amount]]+tbl_Ledger[[#This Row],[Tax Charged on Invoice]] -> 82343
B112: 105 | C112: 46104 | D112: VAT and levies remitted to GRA for March period | E112: Ghana Revenue Authority | F112: Outflow | G112: NO_VAT | H112: 66914 | I112: GRA-2026-0006 | J112: 0 | K112: =IF(INDEX(Cat_ChargesVAT,MATCH(tbl_Ledger[[#This Row],[Tax Category]],Cat_Codes,0))="No",0,tbl_Ledger[[#This Row],[Amount]]*VAT_Rate) -> 0 | L112: =IF(INDEX(Cat_ChargesVAT,MATCH(tbl_Ledger[[#This Row],[Tax Category]],Cat_Codes,0))="No",0,tbl_Ledger[[#This Row],[Amount]]*NHIL_Rate) -> 0 | M112: =IF(INDEX(Cat_ChargesVAT,MATCH(tbl_Ledger[[#This Row],[Tax Category]],Cat_Codes,0))="No",0,tbl_Ledger[[#This Row],[Amount]]*GETFund_Rate) -> 0 | N112: =tbl_Ledger[[#This Row],[Expected VAT]]+tbl_Ledger[[#This Row],[Expected NHIL]]+tbl_Ledger[[#This Row],[Expected GETFund]] -> 0 | O112: =tbl_Ledger[[#This Row],[Amount]]+tbl_Ledger[[#This Row],[Tax Charged on Invoice]] -> 66914
... B120: 113 | C120: 46110 | D120: Office stationery and printing | E120: Adom Telecom Ghana Ltd | F120: Outflow | G120: IN_STD | H120: 2926 | I120: SIN-2026-0039 | J120: 585.2 | K120: =IF(INDEX(Cat_ChargesVAT,MATCH(tbl_Ledger[[#This Row],[Tax Category]],Cat_Codes,0))="No",0,tbl_Ledger[[#This Row],[Amount]]*VAT_Rate) -> 438.9 | L120: =IF(INDEX(Cat_ChargesVAT,MATCH(tbl_Ledger[[#This Row],[Tax Category]],Cat_Codes,0))="No",0,tbl_Ledger[[#This Row],[Amount]]*NHIL_Rate) -> 73.15 | M120: =IF(INDEX(Cat_ChargesVAT,MATCH(tbl_Ledger[[#This Row],[Tax Category]],Cat_Codes,0))="No",0,tbl_Ledger[[#This Row],[Amount]]*GETFund_Rate) -> 73.15 | N120: =tbl_Ledger[[#This Row],[Expected VAT]]+tbl_Ledger[[#This Row],[Expected NHIL]]+tbl_Ledger[[#This Row],[Expected GETFund]] -> 585.2 | O120: =tbl_Ledger[[#This Row],[Amount]]+tbl_Ledger[[#This Row],[Tax Charged on Invoice]] -> 3511.2
B121: 114 | C121: 46110 | D121: Fleet tracking software subscription | E121: Sahara Fleet Services Ltd | F121: Outflow | G121: IN_STD | H121: 8752 | J121: 1750.4 | K121: =IF(INDEX(Cat_ChargesVAT,MATCH(tbl_Ledger[[#This Row],[Tax Category]],Cat_Codes,0))="No",0,tbl_Ledger[[#This Row],[Amount]]*VAT_Rate) -> 1312.8 | L121: =IF(INDEX(Cat_ChargesVAT,MATCH(tbl_Ledger[[#This Row],[Tax Category]],Cat_Codes,0))="No",0,tbl_Ledger[[#This Row],[Amount]]*NHIL_Rate) -> 218.8 | M121: =IF(INDEX(Cat_ChargesVAT,MATCH(tbl_Ledger[[#This Row],[Tax Category]],Cat_Codes,0))="No",0,tbl_Ledger[[#This Row],[Amount]]*GETFund_Rate) -> 218.8 | N121: =tbl_Ledger[[#This Row],[Expected VAT]]+tbl_Ledger[[#This Row],[Expected NHIL]]+tbl_Ledger[[#This Row],[Expected GETFund]] -> 1750.4 | O121: =tbl_Ledger[[#This Row],[Amount]]+tbl_Ledger[[#This Row],[Tax Charged on Invoice]] -> 10502.4
B122: 115 | C122: 46110 | D122: Bulk haulage of AGO, Kumasi-Sunyani, 9 trips | E122: Golden Harmattan Energy Ltd | F122: Inflow | G122: OUT_STD | H122: 72134 | I122: NHL-2026-0051 | J122: 14426.8 | K122: =IF(INDEX(Cat_ChargesVAT,MATCH(tbl_Ledger[[#This Row],[Tax Category]],Cat_Codes,0))="No",0,tbl_Ledger[[#This Row],[Amount]]*VAT_Rate) -> 10820.1 | L122: =IF(INDEX(Cat_ChargesVAT,MATCH(tbl_Ledger[[#This Row],[Tax Category]],Cat_Codes,0))="No",0,tbl_Ledger[[#This Row],[Amount]]*NHIL_Rate) -> 1803.35 | M122: =IF(INDEX(Cat_ChargesVAT,MATCH(tbl_Ledger[[#This Row],[Tax Category]],Cat_Codes,0))="No",0,tbl_Ledger[[#This Row],[Amount]]*GETFund_Rate) -> 1803.35 | N122: =tbl_Ledger[[#This Row],[Expected VAT]]+tbl_Ledger[[#This Row],[Expected NHIL]]+tbl_Ledger[[#This Row],[Expected GETFund]] -> 14426.8 | O122: =tbl_Ledger[[#This Row],[Amount]]+tbl_Ledger[[#This Row],[Tax Charged on Invoice]] -> 86560.8
B123: 116 | C123: 46112 | D123: Staff salaries and wages - March | E123: Nkabom Haulage Payroll | F123: Outflow | G123: NO_VAT | H123: 119432 | I123: PAY-2026-0003 | J123: 0 | K123: =IF(INDEX(Cat_ChargesVAT,MATCH(tbl_Ledger[[#This Row],[Tax Category]],Cat_Codes,0))="No",0,tbl_Ledger[[#This Row],[Amount]]*VAT_Rate) -> 0 | L123: =IF(INDEX(Cat_ChargesVAT,MATCH(tbl_Ledger[[#This Row],[Tax Category]],Cat_Codes,0))="No",0,tbl_Ledger[[#This Row],[Amount]]*NHIL_Rate) -> 0 | M123: =IF(INDEX(Cat_ChargesVAT,MATCH(tbl_Ledger[[#This Row],[Tax Category]],Cat_Codes,0))="No",0,tbl_Ledger[[#This Row],[Amount]]*GETFund_Rate) -> 0 | N123: =tbl_Ledger[[#This Row],[Expected VAT]]+tbl_Ledger[[#This Row],[Expected NHIL]]+tbl_Ledger[[#This Row],[Expected GETFund]] -> 0 | O123: =tbl_Ledger[[#This Row],[Amount]]+tbl_Ledger[[#This Row],[Tax Charged on Invoice]] -> 119432
B124: 117 | C124: 46113 | D124: Year-end staff function | E124: Executive Motors Ltd | F124: Outflow | G124: IN_NONDED | H124: 1376 | I124: SIN-2026-0041 | J124: 275.2 | K124: =IF(INDEX(Cat_ChargesVAT,MATCH(tbl_Ledger[[#This Row],[Tax Category]],Cat_Codes,0))="No",0,tbl_Ledger[[#This Row],[Amount]]*VAT_Rate) -> 206.4 | L124: =IF(INDEX(Cat_ChargesVAT,MATCH(tbl_Ledger[[#This Row],[Tax Category]],Cat_Codes,0))="No",0,tbl_Ledger[[#This Row],[Amount]]*NHIL_Rate) -> 34.4 | M124: =IF(INDEX(Cat_ChargesVAT,MATCH(tbl_Ledger[[#This Row],[Tax Category]],Cat_Codes,0))="No",0,tbl_Ledger[[#This Row],[Amount]]*GETFund_Rate) -> 34.4 | N124: =tbl_Ledger[[#This Row],[Expected VAT]]+tbl_Ledger[[#This Row],[Expected NHIL]]+tbl_Ledger[[#This Row],[Expected GETFund]] -> 275.2 | O124: =tbl_Ledger[[#This Row],[Amount]]+tbl_Ledger[[#This Row],[Tax Charged on Invoice]] -> 1651.2
B125: 118 | C125: 46113 | D125: Depot security services | E125: Greenfield IT Solutions Ltd | F125: Outflow | G125: IN_STD | H125: 5980 | I125: SIN-2026-0042 | J125: 1196 | K125: =IF(INDEX(Cat_ChargesVAT,MATCH(tbl_Ledger[[#This Row],[Tax Category]],Cat_Codes,0))="No",0,tbl_Ledger[[#This Row],[Amount]]*VAT_Rate) -> 897 | L125: =IF(INDEX(Cat_ChargesVAT,MATCH(tbl_Ledger[[#This Row],[Tax Category]],Cat_Codes,0))="No",0,tbl_Ledger[[#This Row],[Amount]]*NHIL_Rate) -> 149.5 | M125: =IF(INDEX(Cat_ChargesVAT,MATCH(tbl_Ledger[[#This Row],[Tax Category]],Cat_Codes,0))="No",0,tbl_Ledger[[#This Row],[Amount]]*GETFund_Rate) -> 149.5 | N125: =tbl_Ledger[[#This Row],[Expected VAT]]+tbl_Ledger[[#This Row],[Expected NHIL]]+tbl_Ledger[[#This Row],[Expected GETFund]] -> 1196 | O125: =tbl_Ledger[[#This Row],[Amount]]+tbl_Ledger[[#This Row],[Tax Charged on Invoice]] -> 7176
B126: 119 | C126: 46117 | D126: Cheque book and facility fees | E126: Trust Union Bank Ltd | F126: Outflow | G126: IN_EXEMPT | H126: 2138 | I126: BNK-2026-0012 | J126: 0 | K126: =IF(INDEX(Cat_ChargesVAT,MATCH(tbl_Ledger[[#This Row],[Tax Category]],Cat_Codes,0))="No",0,tbl_Ledger[[#This Row],[Amount]]*VAT_Rate) -> 0 | L126: =IF(INDEX(Cat_ChargesVAT,MATCH(tbl_Ledger[[#This Row],[Tax Category]],Cat_Codes,0))="No",0,tbl_Ledger[[#This Row],[Amount]]*NHIL_Rate) -> 0 | M126: =IF(INDEX(Cat_ChargesVAT,MATCH(tbl_Ledger[[#This Row],[Tax Category]],Cat_Codes,0))="No",0,tbl_Ledger[[#This Row],[Amount]]*GETFund_Rate) -> 0 | N126: =tbl_Ledger[[#This Row],[Expected VAT]]+tbl_Ledger[[#This Row],[Expected NHIL]]+tbl_Ledger[[#This Row],[Expected GETFund]] -> 0 | O126: =tbl_Ledger[[#This Row],[Amount]]+tbl_Ledger[[#This Row],[Tax Charged on Invoice]] -> 2138
B127: 120 | C127: 46117 | D127: Client entertainment - business development | E127: Sunset Lounge Ltd | F127: Outflow | G127: IN_NONDED | H127: 7230 | I127: SIN-2026-0043 | J127: 1446 | K127: =IF(INDEX(Cat_ChargesVAT,MATCH(tbl_Ledger[[#This Row],[Tax Category]],Cat_Codes,0))="No",0,tbl_Ledger[[#This Row],[Amount]]*VAT_Rate) -> 1084.5 | L127: =IF(INDEX(Cat_ChargesVAT,MATCH(tbl_Ledger[[#This Row],[Tax Category]],Cat_Codes,0))="No",0,tbl_Ledger[[#This Row],[Amount]]*NHIL_Rate) -> 180.75 | M127: =IF(INDEX(Cat_ChargesVAT,MATCH(tbl_Ledger[[#This Row],[Tax Category]],Cat_Codes,0))="No",0,tbl_Ledger[[#This Row],[Amount]]*GETFund_Rate) -> 180.75 | N127: =tbl_Ledger[[#This Row],[Expected VAT]]+tbl_Ledger[[#This Row],[Expected NHIL]]+tbl_Ledger[[#This Row],[Expected GETFund]] -> 1446 | O127: =tbl_Ledger[[#This Row],[Amount]]+tbl_Ledger[[#This Row],[Tax Charged on Invoice]] -> 8676
...

Sheet VAT_Recon
B1: NKABOM HAULAGE LTD — CORE TAX ENGINE
B2: Sheet 4 of 6 • Monthly VAT & Levy Reconciliation • Simulation period January to August 2026
B3: SIMULATION ONLY — figures are fictitious. Every amount below is a formula reading the Ledger; nothing on this sheet is typed. Not a filed return and not tax advice.
B5: A. MONTHLY VAT AND LEVY RECONCILIATION
C6: OUTPUT TAX — charged on supplies made | F6: INPUT TAX — incurred on supplies received
B7: Month | C7: Output VAT | D7: Output NHIL | E7: Output GETFund | F7: Input VAT | G7: Input NHIL | H7: Input GETFund | I7: Net VAT Payable / (Recoverable) | J7: Sense check
B8: Ledger Direction filter applied → | C8: Inflow | D8: Inflow | E8: Inflow | F8: Outflow | G8: Outflow | H8: Outflow
B9: =DATE(Ledger_Year,1,1) -> 46023 | C9: {=SUMPRODUCT((YEAR(Ledger!$C$8:$C$307)=YEAR($B9))*(MONTH(Ledger!$C$8:$C$307)=MONTH($B9))*(Ledger!$F$8:$F$307=C$8)*(INDEX(Cat_ChargesVAT,MATCH(Ledger!$G$8:$G$307,Cat_Codes,0))="Yes")*Ledger!$K$8:$K$307)} -> 195161.4 | D9: {=SUMPRODUCT((YEAR(Ledger!$C$8:$C$307)=YEAR($B9))*(MONTH(Ledger!$C$8:$C$307)=MONTH($B9))*(Ledger!$F$8:$F$307=D$8)*(INDEX(Cat_ChargesVAT,MATCH(Ledger!$G$8:$G$307,Cat_Codes,0))="Yes")*Ledger!$L$8:$L$307)} -> 32526.9 | E9: {=SUMPRODUCT((YEAR(Ledger!$C$8:$C$307)=YEAR($B9))*(MONTH(Ledger!$C$8:$C$307)=MONTH($B9))*(Ledger!$F$8:$F$307=E$8)*(INDEX(Cat_ChargesVAT,MATCH(Ledger!$G$8:$G$307,Cat_Codes,0))="Yes")*Ledger!$M$8:$M$307)} -> 32526.9 | F9: {=SUMPRODUCT((YEAR(Ledger!$C$8:$C$307)=YEAR($B9))*(MONTH(Ledger!$C$8:$C$307)=MONTH($B9))*(Ledger!$F$8:$F$307=F$8)*(INDEX(Cat_Recoverable,MATCH(Ledger!$G$8:$G$307,Cat_Codes,0))="Yes")*Ledger!$K$8:$K$307)} -> 14008.95 | G9: {=SUMPRODUCT((YEAR(Ledger!$C$8:$C$307)=YEAR($B9))*(MONTH(Ledger!$C$8:$C$307)=MONTH($B9))*(Ledger!$F$8:$F$307=G$8)*(INDEX(Cat_Recoverable,MATCH(Ledger!$G$8:$G$307,Cat_Codes,0))="Yes")*Ledger!$L$8:$L$307)} -> 2334.825 | H9: {=SUMPRODUCT((YEAR(Ledger!$C$8:$C$307)=YEAR($B9))*(MONTH(Ledger!$C$8:$C$307)=MONTH($B9))*(Ledger!$F$8:$F$307=H$8)*(INDEX(Cat_Recoverable,MATCH(Ledger!$G$8:$G$307,Cat_Codes,0))="Yes")*Ledger!$M$8:$M$307)} -> 2334.825 | I9: =(C9+D9+E9)-(F9+G9+H9) -> 241536.6 | J9: =IF(I9<0,"Net credit — review","Net payable") -> Net payable
B10: =EDATE(B9,1) -> 46054 | C10: {=SUMPRODUCT((YEAR(Ledger!$C$8:$C$307)=YEAR($B10))*(MONTH(Ledger!$C$8:$C$307)=MONTH($B10))*(Ledger!$F$8:$F$307=C$8)*(INDEX(Cat_ChargesVAT,MATCH(Ledger!$G$8:$G$307,Cat_Codes,0))="Yes")*Ledger!$K$8:$K$307)} -> 134963.85 | D10: {=SUMPRODUCT((YEAR(Ledger!$C$8:$C$307)=YEAR($B10))*(MONTH(Ledger!$C$8:$C$307)=MONTH($B10))*(Ledger!$F$8:$F$307=D$8)*(INDEX(Cat_ChargesVAT,MATCH(Ledger!$G$8:$G$307,Cat_Codes,0))="Yes")*Ledger!$L$8:$L$307)} -> 22493.975 | E10: {=SUMPRODUCT((YEAR(Ledger!$C$8:$C$307)=YEAR($B10))*(MONTH(Ledger!$C$8:$C$307)=MONTH($B10))*(Ledger!$F$8:$F$307=E$8)*(INDEX(Cat_ChargesVAT,MATCH(Ledger!$G$8:$G$307,Cat_Codes,0))="Yes")*Ledger!$M$8:$M$307)} -> 22493.975 | F10: {=SUMPRODUCT((YEAR(Ledger!$C$8:$C$307)=YEAR($B10))*(MONTH(Ledger!$C$8:$C$307)=MONTH($B10))*(Ledger!$F$8:$F$307=F$8)*(INDEX(Cat_Recoverable,MATCH(Ledger!$G$8:$G$307,Cat_Codes,0))="Yes")*Ledger!$K$8:$K$307)} -> 11309.25 | G10: {=SUMPRODUCT((YEAR(Ledger!$C$8:$C$307)=YEAR($B10))*(MONTH(Ledger!$C$8:$C$307)=MONTH($B10))*(Ledger!$F$8:$F$307=G$8)*(INDEX(Cat_Recoverable,MATCH(Ledger!$G$8:$G$307,Cat_Codes,0))="Yes")*Ledger!$L$8:$L$307)} -> 1884.875 | H10: {=SUMPRODUCT((YEAR(Ledger!$C$8:$C$307)=YEAR($B10))*(MONTH(Ledger!$C$8:$C$307)=MONTH($B10))*(Ledger!$F$8:$F$307=H$8)*(INDEX(Cat_Recoverable,MATCH(Ledger!$G$8:$G$307,Cat_Codes,0))="Yes")*Ledger!$M$8:$M$307)} -> 1884.875 | I10: =(C10+D10+E10)-(F10+G10+H10) -> 164872.8 | J10: =IF(I10<0,"Net credit — review","Net payable") -> Net payable
B11: =EDATE(B10,1) -> 46082 | C11: {=SUMPRODUCT((YEAR(Ledger!$C$8:$C$307)=YEAR($B11))*(MONTH(Ledger!$C$8:$C$307)=MONTH($B11))*(Ledger!$F$8:$F$307=C$8)*(INDEX(Cat_ChargesVAT,MATCH(Ledger!$G$8:$G$307,Cat_Codes,0))="Yes")*Ledger!$K$8:$K$307)} -> 159072.9 | D11: {=SUMPRODUCT((YEAR(Ledger!$C$8:$C$307)=YEAR($B11))*(MONTH(Ledger!$C$8:$C$307)=MONTH($B11))*(Ledger!$F$8:$F$307=D$8)*(INDEX(Cat_ChargesVAT,MATCH(Ledger!$G$8:$G$307,Cat_Codes,0))="Yes")*Ledger!$L$8:$L$307)} -> 26512.15 | E11: {=SUMPRODUCT((YEAR(Ledger!$C$8:$C$307)=YEAR($B11))*(MONTH(Ledger!$C$8:$C$307)=MONTH($B11))*(Ledger!$F$8:$F$307=E$8)*(INDEX(Cat_ChargesVAT,MATCH(Ledger!$G$8:$G$307,Cat_Codes,0))="Yes")*Ledger!$M$8:$M$307)} -> 26512.15 | F11: {=SUMPRODUCT((YEAR(Ledger!$C$8:$C$307)=YEAR($B11))*(MONTH(Ledger!$C$8:$C$307)=MONTH($B11))*(Ledger!$F$8:$F$307=F$8)*(INDEX(Cat_Recoverable,MATCH(Ledger!$G$8:$G$307,Cat_Codes,0))="Yes")*Ledger!$K$8:$K$307)} -> 11403 | G11: {=SUMPRODUCT((YEAR(Ledger!$C$8:$C$307)=YEAR($B11))*(MONTH(Ledger!$C$8:$C$307)=MONTH($B11))*(Ledger!$F$8:$F$307=G$8)*(INDEX(Cat_Recoverable,MATCH(Ledger!$G$8:$G$307,Cat_Codes,0))="Yes")*Ledger!$L$8:$L$307)} -> 1900.5 | H11: {=SUMPRODUCT((YEAR(Ledger!$C$8:$C$307)=YEAR($B11))*(MONTH(Ledger!$C$8:$C$307)=MONTH($B11))*(Ledger!$F$8:$F$307=H$8)*(INDEX(Cat_Recoverable,MATCH(Ledger!$G$8:$G$307,Cat_Codes,0))="Yes")*Ledger!$M$8:$M$307)} -> 1900.5 | I11: =(C11+D11+E11)-(F11+G11+H11) -> 196893.2 | J11: =IF(I11<0,"Net credit — review","Net payable") -> Net payable
